Workbook

Sheet RQ1_raw
A1: RQ1: root-cause localization, N=235, five runs per method
A3: Method | B3: top1 run1 | C3: run2 | D3: run3 | E3: run4 | F3: run5 | G3: mean k | H3: Top-1 mean % | I3: Top-1 std (pp) | J3: top3 run1 | K3: run2 | L3: run3 | M3: run4 | N3: run5 | O3: mean k | P3: Top-3 mean % | Q3: Top-3 std (pp) | R3: F1 run1 | S3: run2 | T3: run3 | U3: run4 | V3: run5 | W3: F1 mean | X3: F1 std
A4: B3: Random / Majority | B4: 9 | C4: 10 | D4: 9 | E4: 10 | F4: 7 | G4: =AVERAGE(B4:F4) -> 9 | H4: =G4/235*100 -> 3.8297872 | I4: =STDEV(B4:F4)*100/235 -> 0.52116803 | J4: 45 | K4: 47 | L4: 44 | M4: 48 | N4: 47 | O4: =AVERAGE(J4:N4) -> 46.2 | P4: =O4/235*100 -> 19.659574 | Q4: =STDEV(K4:O4)*100/235 -> 0.64084598 | R4: =F1_raw!H4 -> 0.09 | S4: =F1_raw!H5 -> 0.09 | T4: =F1_raw!H6 -> 0.09 | U4: =F1_raw!H7 -> 0.08 | V4: =F1_raw!H8 -> 0.1 | W4: =AVERAGE(R4:V4) -> 0.09 | X4: =STDEV(R4:V4) -> 0.0070710678
A5: B2: DeepSeek-V4 (direct reading) | B5: 82 | C5: 81 | D5: 81 | E5: 80 | F5: 81 | G5: =AVERAGE(B5:F5) -> 81 | H5: =G5/235*100 -> 34.468085 | I5: =STDEV(B5:F5)*100/235 -> 0.3008965 | J5: 139 | K5: 138 | L5: 137 | M5: 138 | N5: 138 | O5: =AVERAGE(J5:N5) -> 138 | P5: =O5/235*100 -> 58.723404 | Q5: =STDEV(K5:O5)*100/235 -> 0.19030366 | R5: =F1_raw!H9 -> 0.22222222 | S5: =F1_raw!H10 -> 0.22110553 | T5: =F1_raw!H11 -> 0.22110553 | U5: =F1_raw!H12 -> 0.21212121 | V5: =F1_raw!H13 -> 0.22110553 | W5: =AVERAGE(R5:V5) -> 0.219532 | X5: =STDEV(R5:V5) -> 0.0041708824
A6: B1: GPT-4o (direct reading) | B6: 69 | C6: 67 | D6: 66 | E6: 67 | F6: 66 | G6: =AVERAGE(B6:F6) -> 67 | H6: =G6/235*100 -> 28.510638 | I6: =STDEV(B6:F6)*100/235 -> 0.52116803 | J6: 119 | K6: 118 | L6: 117 | M6: 118 | N6: 118 | O6: =AVERAGE(J6:N6) -> 118 | P6: =O6/235*100 -> 50.212766 | Q6: =STDEV(K6:O6)*100/235 -> 0.19030366 | R6: =F1_raw!H14 -> 0.16 | S6: =F1_raw!H15 -> 0.16 | T6: =F1_raw!H16 -> 0.16 | U6: =F1_raw!H17 -> 0.15 | V6: =F1_raw!H18 -> 0.17 | W6: =AVERAGE(R6:V6) -> 0.16 | X6: =STDEV(R6:V6) -> 0.0070710678
A7: CauseFlow (full) | B7: 145 | C7: 153 | D7: 150 | E7: 149 | F7: 149 | G7: =AVERAGE(B7:F7) -> 149.2 | H7: =G7/235*100 -> 63.489362 | I7: =STDEV(B7:F7)*100/235 -> 1.218538 | J7: 215 | K7: 213 | L7: 209 | M7: 212 | N7: 211 | O7: =AVERAGE(J7:N7) -> 212 | P7: =O7/235*100 -> 90.212766 | Q7: =STDEV(K7:O7)*100/235 -> 0.6453511 | R7: =F1_raw!H19 -> 0.47 | S7: =F1_raw!H20 -> 0.47 | T7: =F1_raw!H21 -> 0.47 | U7: =F1_raw!H22 -> 0.46 | V7: =F1_raw!H23 -> 0.48 | W7: =AVERAGE(R7:V7) -> 0.47 | X7: =STDEV(R7:V7) -> 0.0070710678
A9: Gaps (pp): | B9: =ROUND(H7,2)-ROUND(H5,2) -> 29.02 | C9: <- CauseFlow - B2 (top-1, pp) | D9: =ROUND(H7,2)-ROUND(H6,2) -> 34.98 | E9: <- CauseFlow - B1 (top-1, pp)

Sheet RQ2_static
A1: RQ2: repair on 70 failed ITBench trajectories
A3: Method | B3: repaired k | C3: N | D3: repair % | E3: intent k | F3: intent % | G3: avg edited tokens | H3: cost USD/traj
A4: No repair (identity re-run) | B4: 0 | C4: 70 | D4: =B4/C4*100 -> 0 | E4: - | F4: - | G4: -- | H4: --
A5: B2: DeepSeek-V4 (direct) | B5: 4 | C5: 70 | D5: =B5/C5*100 -> 5.7142857 | E5: 54 | F5: =IF(E5="-","-",E5/C5*100) -> 77.142857 | G5: 176 | H5: 0.35
A6: B1: GPT-4o (direct) | B6: 7 | C6: 70 | D6: =B6/C6*100 -> 10 | E6: 57 | F6: =IF(E6="-","-",E6/C6*100) -> 81.428571 | G6: 148 | H6: 2.31
A7: CauseFlow (full) | B7: 20 | C7: 70 | D7: =B7/C7*100 -> 28.571429 | E7: 67 | F7: =IF(E7="-","-",E7/C7*100) -> 95.714286 | G7: 42 | H7: 1.12
A9: Ratios / gaps: | B9: =B7/B6 -> 2.8571429 | C9: success ratio CF/B1 | D9: =G6/G7 -> 3.5238095 | E9: edit-size ratio B1/CF | F9: =ROUND(D7,2)-ROUND(D6,2) -> 18.57 | G9: repair gap vs B1 (pp) | H9: =ROUND(D7,2)-ROUND(D5,2) -> 22.86 | I9: repair gap vs B2 (pp)
A10: Wilson 95% CI for CF 20/70: | B10: 19.32 | C10: lower bound (%) | D10: 40.05 | E10: upper bound (%)
A11: Wilson 95% CI for B1 7/70: | B11: 4.93 | C11: lower bound (%) | D11: 19.23 | E11: upper bound (%) | F11: paired McNemar exact p = 0.000977
A13: repair rate vs no-repair (pp): | B13: =ROUND(D7,2)-ROUND(D4,2) -> 28.57

Sheet RQ3_raw
A1: RQ3: component ablation, N=150, five runs per variant
A3: Variant | B3: top1 run1 | C3: run2 | D3: run3 | E3: run4 | F3: run5 | G3: mean k | H3: Top-1 mean % | I3: Top-1 std (pp) | J3: F1 run1 | K3: run2 | L3: run3 | M3: run4 | N3: run5 | O3: F1 mean | P3: F1 std | Q3: drop vs full (pp)
A4: w/o Compression | B4: 42 | C4: 47 | D4: 41 | E4: 54 | F4: 52 | G4: =AVERAGE(B4:F4) -> 47.2 | H4: =G4/150*100 -> 31.466667 | I4: =STDEV(B4:F4)*100/150 -> 3.8701134 | J4: =F1_raw!H24 -> 0.34666667 | K4: =F1_raw!H25 -> 0.35 | L4: =F1_raw!H26 -> 0.35 | M4: =F1_raw!H27 -> 0.35 | N4: =F1_raw!H28 -> 0.35333333 | O4: =AVERAGE(J4:N4) -> 0.35 | P4: =STDEV(J4:N4) -> 0.0023570226 | Q4: =ROUND(H$10,2)-ROUND(H4,2) -> 31.86
A5: w/o SF (HS + KI only) | B5: 60 | C5: 53 | D5: 52 | E5: 56 | F5: 54 | G5: =AVERAGE(B5:F5) -> 55 | H5: =G5/150*100 -> 36.666667 | I5: =STDEV(B5:F5)*100/150 -> 2.1081851 | J5: =F1_raw!H29 -> 0.40666667 | K5: =F1_raw!H30 -> 0.41 | L5: =F1_raw!H31 -> 0.41 | M5: =F1_raw!H32 -> 0.41 | N5: =F1_raw!H33 -> 0.41333333 | O5: =AVERAGE(J5:N5) -> 0.41 | P5: =STDEV(J5:N5) -> 0.0023570226 | Q5: =ROUND(H$10,2)-ROUND(H5,2) -> 26.66
A6: w/o HS (SF + KI only) | B6: 63 | C6: 61 | D6: 55 | E6: 57 | F6: 55 | G6: =AVERAGE(B6:F6) -> 58.2 | H6: =G6/150*100 -> 38.8 | I6: =STDEV(B6:F6)*100/150 -> 2.4221203 | J6: =F1_raw!H34 -> 0.42666667 | K6: =F1_raw!H35 -> 0.43 | L6: =F1_raw!H36 -> 0.43 | M6: =F1_raw!H37 -> 0.43 | N6: =F1_raw!H38 -> 0.43333333 | O6: =AVERAGE(J6:N6) -> 0.43 | P6: =STDEV(J6:N6) -> 0.0023570226 | Q6: =ROUND(H$10,2)-ROUND(H6,2) -> 24.53
A7: w/o KI (SF + HS only) | B7: 51 | C7: 51 | D7: 48 | E7: 52 | F7: 55 | G7: =AVERAGE(B7:F7) -> 51.4 | H7: =G7/150*100 -> 34.266667 | I7: =STDEV(B7:F7)*100/150 -> 1.6733201 | J7: =F1_raw!H39 -> 0.36666667 | K7: =F1_raw!H40 -> 0.37 | L7: =F1_raw!H41 -> 0.37 | M7: =F1_raw!H42 -> 0.37 | N7: =F1_raw!H43 -> 0.37333333 | O7: =AVERAGE(J7:N7) -> 0.37 | P7: =STDEV(J7:N7) -> 0.0023570226 | Q7: =ROUND(H$10,2)-ROUND(H7,2) -> 29.06
A8: w/o LLM reasoning (rule-based) | B8: 51 | C8: 54 | D8: 49 | E8: 56 | F8: 54 | G8: =AVERAGE(B8:F8) -> 52.8 | H8: =G8/150*100 -> 35.2 | I8: =STDEV(B8:F8)*100/150 -> 1.8499249 | J8: =F1_raw!H44 -> 0.38666667 | K8: =F1_raw!H45 -> 0.39 | L8: =F1_raw!H46 -> 0.39 | M8: =F1_raw!H47 -> 0.39 | N8: =F1_raw!H48 -> 0.39333333 | O8: =AVERAGE(J8:N8) -> 0.39 | P8: =STDEV(J8:N8) -> 0.0023570226 | Q8: =ROUND(H$10,2)-ROUND(H8,2) -> 28.13
A9: w/o Attribution paths (same reasoner) | B9: 45 | C9: 44 | D9: 44 | E9: 43 | F9: 44 | G9: =AVERAGE(B9:F9) -> 44 | H9: =G9/150*100 -> 29.333333 | I9: =STDEV(B9:F9)*100/150 -> 0.47140452 | J9: =F1_raw!H49 -> 0.31666667 | K9: =F1_raw!H50 -> 0.32 | L9: =F1_raw!H51 -> 0.32 | M9: =F1_raw!H52 -> 0.32 | N9: =F1_raw!H53 -> 0.32333333 | O9: =AVERAGE(J9:N9) -> 0.32 | P9: =STDEV(J9:N9) -> 0.0023570226 | Q9: =ROUND(H$10,2)-ROUND(H9,2) -> 34
A10: CauseFlow (full) | B10: 95 | C10: 95 | D10: 94 | E10: 96 | F10: 95 | G10: =AVERAGE(B10:F10) -> 95 | H10: =G10/150*100 -> 63.333333 | I10: =STDEV(B10:F10)*100/150 -> 0.47140452 | J10: =F1_raw!H54 -> 0.46666667 | K10: =F1_raw!H55 -> 0.47 | L10: =F1_raw!H56 -> 0.47 | M10: =F1_raw!H57 -> 0.47 | N10: =F1_raw!H58 -> 0.47333333 | O10: =AVERAGE(J10:N10) -> 0.47 | P10: =STDEV(J10:N10) -> 0.0023570226 | Q10: =ROUND(H$10,2)-ROUND(H10,2) -> 0

Sheet RQ4_static
A1: RQ4: stratified Top-1 on the 235 trajectories (median run)
A3: Dimension | B3: Stratum | C3: top1 k | D3: top3 k | E3: N | F3: Top-1 %
A4: categories | B4: software engineering | C4: 70 | D4: 98 | E4: 107 | F4: =C4/E4*100 -> 65.420561
A5: categories | B5: system administration | C5: 11 | D5: 16 | E5: 18 | F5: =C5/E5*100 -> 61.111111
A6: categories | B6: scientific computing | C6: 9 | D6: 13 | E6: 15 | F6: =C6/E6*100 -> 60
A7: categories | B7: model training | C7: 9 | D7: 12 | E7: 14 | F7: =C7/E7*100 -> 64.285714
A8: categories | B8: security | C8: 8 | D8: 11 | E8: 13 | F8: =C8/E8*100 -> 61.538462
A9: categories | B9: data science | C9: 7 | D9: 10 | E9: 11 | F9: =C9/E9*100 -> 63.636364
A10: categories | B10: others (pooled) | C10: 35 | D10: 52 | E10: 57 | F10: =C10/E10*100 -> 61.403509
A12: backbones | B12: GPT-5 | C12: 43 | D12: 63 | E12: 69 | F12: =C12/E12*100 -> 62.318841
A13: backbones | B13: Claude-Sonnet-4 | C13: 64 | D13: 93 | E13: 104 | F13: =C13/E13*100 -> 61.538462
A14: backbones | B14: DeepSeek-V4 | C14: 42 | D14: 56 | E14: 62 | F14: =C14/E14*100 -> 67.741935
A16: lengths | B16: short (<=30) | C16: 49 | D16: 67 | E16: 73 | F16: =C16/E16*100 -> 67.123288
A17: lengths | B17: medium (31-80) | C17: 78 | D17: 111 | E17: 124 | F17: =C17/E17*100 -> 62.903226
A18: lengths | B18: long (>80) | C18: 22 | D18: 34 | E18: 38 | F18: =C18/E18*100 -> 57.894737
A20: All | B20: total (sum of categories) | C20: =SUM(C4:C10) -> 149 | D20: =SUM(D4:D10) -> 212 | E20: 235 | F20: =C20/E20*100 -> 63.404255
A21: backbone spread DS - Claude (pp) | E21: =ROUND(42/62*100,2)-ROUND(64/104*100,2) -> 6.2
A23: min backbone gap vs strongest baseline (pp) | E23: =ROUND(64/104*100,2)-34.46 -> 27.08
A24: B1 short stratum | B24: 25 | C24: 73 | E24: =25/73*100 -> 34.246575
A25: B1 long stratum | B25: 5 | C25: 38 | E25: =5/38*100 -> 13.157895
A26: long-trajectory gap CF - B1 (pp) | E26: =ROUND(22/38*100,2)-ROUND(5/38*100,2) -> 44.73
A27: overall gap CF - B1 (pp) | E27: =ROUND(RQ1_raw!H7,2)-ROUND(RQ1_raw!H6,2) -> 34.98
A28: B1 relative decay short->long | E28: =(25/73-5/38)/(25/73)*100 -> 61.578947
A29: CF relative decay short->long | E29: =(49/73-22/38)/(49/73)*100 -> 13.748657

Sheet F1_raw
A1: F1 derivation: RQ1 set-level over 56 distinct incorrect steps (P = TP/pred, R = TP/56, F1 = 2*TP/(pred+56)); RQ3 subset records (F1 = 2*TP/(pred+N))
A3: Section | B3: Method | C3: run | D3: TP | E3: pred | F3: P | G3: R | H3: F1
A4: RQ1 | B4: B3: Random / Majority | C4: 1 | D4: 9 | E4: 144 | F4: =D4/E4 -> 0.0625 | G4: =D4/56 -> 0.16071429 | H4: =2*D4/(E4+56) -> 0.09
A5: RQ1 | B5: B3: Random / Majority | C5: 2 | D5: 9 | E5: 144 | F5: =D5/E5 -> 0.0625 | G5: =D5/56 -> 0.16071429 | H5: =2*D5/(E5+56) -> 0.09
A6: RQ1 | B6: B3: Random / Majority | C6: 3 | D6: 9 | E6: 144 | F6: =D6/E6 -> 0.0625 | G6: =D6/56 -> 0.16071429 | H6: =2*D6/(E6+56) -> 0.09
A7: RQ1 | B7: B3: Random / Majority | C7: 4 | D7: 8 | E7: 144 | F7: =D7/E7 -> 0.055555556 | G7: =D7/56 -> 0.14285714 | H7: =2*D7/(E7+56) -> 0.08
A8: RQ1 | B8: B3: Random / Majority | C8: 5 | D8: 10 | E8: 144 | F8: =D8/E8 -> 0.069444444 | G8: =D8/56 -> 0.17857143 | H8: =2*D8/(E8+56) -> 0.1
A9: RQ1 | B9: B2: DeepSeek-V4 (direct reading) | C9: 1 | D9: 22 | E9: 142 | F9: =D9/E9 -> 0.15492958 | G9: =D9/56 -> 0.39285714 | H9: =2*D9/(E9+56) -> 0.22222222
A10: RQ1 | B10: B2: DeepSeek-V4 (direct reading) | C10: 2 | D10: 22 | E10: 143 | F10: =D10/E10 -> 0.15384615 | G10: =D10/56 -> 0.39285714 | H10: =2*D10/(E10+56) -> 0.22110553
A11: RQ1 | B11: B2: DeepSeek-V4 (direct reading) | C11: 3 | D11: 22 | E11: 143 | F11: =D11/E11 -> 0.15384615 | G11: =D11/56 -> 0.39285714 | H11: =2*D11/(E11+56) -> 0.22110553
A12: RQ1 | B12: B2: DeepSeek-V4 (direct reading) | C12: 4 | D12: 21 | E12: 142 | F12: =D12/E12 -> 0.14788732 | G12: =D12/56 -> 0.375 | H12: =2*D12/(E12+56) -> 0.21212121
A13: RQ1 | B13: B2: DeepSeek-V4 (direct reading) | C13: 5 | D13: 22 | E13: 143 | F13: =D13/E13 -> 0.15384615 | G13: =D13/56 -> 0.39285714 | H13: =2*D13/(E13+56) -> 0.22110553
A14: RQ1 | B14: B1: GPT-4o (direct reading) | C14: 1 | D14: 16 | E14: 144 | F14: =D14/E14 -> 0.11111111 | G14: =D14/56 -> 0.28571429 | H14: =2*D14/(E14+56) -> 0.16
A15: RQ1 | B15: B1: GPT-4o (direct reading) | C15: 2 | D15: 16 | E15: 144 | F15: =D15/E15 -> 0.11111111 | G15: =D15/56 -> 0.28571429 | H15: =2*D15/(E15+56) -> 0.16
... A23: RQ1 | B23: CauseFlow (full) | C23: 5 | D23: 48 | E23: 144 | F23: =D23/E23 -> 0.33333333 | G23: =D23/56 -> 0.85714286 | H23: =2*D23/(E23+56) -> 0.48
A24: RQ3 | B24: w/o Compression | C24: 1 | D24: 104 | E24: 450 | F24: =D24/E24 -> 0.23111111 | G24: =D24/150 -> 0.69333333 | H24: =2*D24/(E24+150) -> 0.34666667
A25: RQ3 | B25: w/o Compression | C25: 2 | D25: 105 | E25: 450 | F25: =D25/E25 -> 0.23333333 | G25: =D25/150 -> 0.7 | H25: =2*D25/(E25+150) -> 0.35
A26: RQ3 | B26: w/o Compression | C26: 3 | D26: 105 | E26: 450 | F26: =D26/E26 -> 0.23333333 | G26: =D26/150 -> 0.7 | H26: =2*D26/(E26+150) -> 0.35
A27: RQ3 | B27: w/o Compression | C27: 4 | D27: 105 | E27: 450 | F27: =D27/E27 -> 0.23333333 | G27: =D27/150 -> 0.7 | H27: =2*D27/(E27+150) -> 0.35
A28: RQ3 | B28: w/o Compression | C28: 5 | D28: 106 | E28: 450 | F28: =D28/E28 -> 0.23555556 | G28: =D28/150 -> 0.70666667 | H28: =2*D28/(E28+150) -> 0.35333333
A29: RQ3 | B29: w/o SF (HS + KI only) | C29: 1 | D29: 122 | E29: 450 | F29: =D29/E29 -> 0.27111111 | G29: =D29/150 -> 0.81333333 | H29: =2*D29/(E29+150) -> 0.40666667
A30: RQ3 | B30: w/o SF (HS + KI only) | C30: 2 | D30: 123 | E30: 450 | F30: =D30/E30 -> 0.27333333 | G30: =D30/150 -> 0.82 | H30: =2*D30/(E30+150) -> 0.41
A31: RQ3 | B31: w/o SF (HS + KI only) | C31: 3 | D31: 123 | E31: 450 | F31: =D31/E31 -> 0.27333333 | G31: =D31/150 -> 0.82 | H31: =2*D31/(E31+150) -> 0.41
A32: RQ3 | B32: w/o SF (HS + KI only) | C32: 4 | D32: 123 | E32: 450 | F32: =D32/E32 -> 0.27333333 | G32: =D32/150 -> 0.82 | H32: =2*D32/(E32+150) -> 0.41
A33: RQ3 | B33: w/o SF (HS + KI only) | C33: 5 | D33: 124 | E33: 450 | F33: =D33/E33 -> 0.27555556 | G33: =D33/150 -> 0.82666667 | H33: =2*D33/(E33+150) -> 0.41333333
A34: RQ3 | B34: w/o HS (SF + KI only) | C34: 1 | D34: 128 | E34: 450 | F34: =D34/E34 -> 0.28444444 | G34: =D34/150 -> 0.85333333 | H34: =2*D34/(E34+150) -> 0.42666667
A35: RQ3 | B35: w/o HS (SF + KI only) | C35: 2 | D35: 129 | E35: 450 | F35: =D35/E35 -> 0.28666667 | G35: =D35/150 -> 0.86 | H35: =2*D35/(E35+150) -> 0.43
... A58: RQ3 | B58: CauseFlow (full) | C58: 5 | D58: 142 | E58: 450 | F58: =D58/E58 -> 0.31555556 | G58: =D58/150 -> 0.94666667 | H58: =2*D58/(E58+150) -> 0.47333333
A60: Summary (mean over the five runs; F1 std sample n-1)
A61: Section | B61: Method | C61: P mean | D61: R mean | E61: F1 mean | F61: F1 std
A62: RQ1 | B62: B3: Random / Majority | C62: =AVERAGE(F4:F8) -> 0.0625 | D62: =AVERAGE(G4:G8) -> 0.16071429 | E62: =AVERAGE(H4:H8) -> 0.09 | F62: =STDEV(H4:H8) -> 0.0070710678
A63: RQ1 | B63: B2: DeepSeek-V4 (direct reading) | C63: =AVERAGE(F9:F13) -> 0.15287107 | D63: =AVERAGE(G9:G13) -> 0.38928571 | E63: =AVERAGE(H9:H13) -> 0.219532 | F63: =STDEV(H9:H13) -> 0.0041708824
A64: RQ1 | B64: B1: GPT-4o (direct reading) | C64: =AVERAGE(F14:F18) -> 0.11111111 | D64: =AVERAGE(G14:G18) -> 0.28571429 | E64: =AVERAGE(H14:H18) -> 0.16 | F64: =STDEV(H14:H18) -> 0.0070710678
A65: RQ1 | B65: CauseFlow (full) | C65: =AVERAGE(F19:F23) -> 0.32638889 | D65: =AVERAGE(G19:G23) -> 0.83928571 | E65: =AVERAGE(H19:H23) -> 0.47 | F65: =STDEV(H19:H23) -> 0.0070710678
A67: RQ3 | B67: w/o Compression | C67: =AVERAGE(F24:F28) -> 0.23333333 | D67: =AVERAGE(G24:G28) -> 0.7 | E67: =AVERAGE(H24:H28) -> 0.35 | F67: =STDEV(H24:H28) -> 0.0023570226
A68: RQ3 | B68: w/o SF (HS + KI only) | C68: =AVERAGE(F29:F33) -> 0.27333333 | D68: =AVERAGE(G29:G33) -> 0.82 | E68: =AVERAGE(H29:H33) -> 0.41 | F68: =STDEV(H29:H33) -> 0.0023570226
A69: RQ3 | B69: w/o HS (SF + KI only) | C69: =AVERAGE(F34:F38) -> 0.28666667 | D69: =AVERAGE(G34:G38) -> 0.86 | E69: =AVERAGE(H34:H38) -> 0.43 | F69: =STDEV(H34:H38) -> 0.0023570226
A70: RQ3 | B70: w/o KI (SF + HS only) | C70: =AVERAGE(F39:F43) -> 0.24666667 | D70: =AVERAGE(G39:G43) -> 0.74 | E70: =AVERAGE(H39:H43) -> 0.37 | F70: =STDEV(H39:H43) -> 0.0023570226
A71: RQ3 | B71: w/o LLM reasoning (rule-based) | C71: =AVERAGE(F44:F48) -> 0.26 | D71: =AVERAGE(G44:G48) -> 0.78 | E71: =AVERAGE(H44:H48) -> 0.39 | F71: =STDEV(H44:H48) -> 0.0023570226
A72: RQ3 | B72: w/o Attribution paths (same reasoner) | C72: =AVERAGE(F49:F53) -> 0.21333333 | D72: =AVERAGE(G49:G53) -> 0.64 | E72: =AVERAGE(H49:H53) -> 0.32 | F72: =STDEV(H49:H53) -> 0.0023570226
...
